Workbook
Name AVGDISCSP1Y: Summary!$E$5
Name AVGDISCSP3Y: Summary!$E$6
Name CSVPATH: Parameters!$B$10
Name CURR: Parameters!$B$5
Name CUSTNAME: Parameters!$B$4
Name GROWTH: Parameters!$B$9
Name PAYGDISC: Parameters!$B$6
Name RIEXTRADISC: Parameters!$B$7
Name SPCOMMIT: SavingsPlan!$C$11
Name SPDISC: SavingsPlan!$C$10
Name SPEXTRADISC: Parameters!$B$8

Sheet VersionHistory
A1: Version History
A2: Version | B2: Date | C2: Name | D2: Email | E2: Comment
A3: 2 | B3: 46178 | C3: Donovan Hughes | D3: dohughes@microsoft.com | E3: Written to collect data via script and import via Power Query

Sheet Intro
A1: How much should I invest in Azure Savings Plan for Compute?
A3: I need to know: | I3: Starter strategy | N3: Aggressive strategy
A4: 1. How much am I spending today on eligible services?
A5: 2. Do I expect this pattern to continue? | I5: More flexibility | L5: 10% - 20% PAYG | N5: More flexibility | Q5: 10% PAYG
A6: 3. What is my preferred commitment level versus PAYG margin? See here ====> | Q6: 20% Savings Plan
A7: 4. What services am I using today? (discounts vary) | L7: 20% - 30% Savings Plan
A8: 5. What is my exit strategy if I no longer need the savings plan? | Q8: 70% Reservations
L10: 50% - 60% Reservations
I13: More discount | N13: More discount
I17: Low-maintenance strategy
I19: More flexibility | L19: 10% - 20% PAYG
L21: 60% - 70% Savings Plan
I27: More discount | L27: 10% - 20% Reservations

Sheet Instructions
A1: How to use this calculator
A3: Introduction | B3: This Excel calculator is designed to help Azure customers calculate an appropriate amount of Azure Savings Plan for Compute to buy, based on their historical consumption. This file is part of a package together with PowerShell scripts that perform the data collection. Before using this tool, make sure the two CSV output files are present and make a note of their location.
C5: Collector script | D5: CSV location
A6: Datasets | B6: 1. Last 6 months' Azure spend on virtual machines, grouped by pricing model (PAYG, Reservations, and Savings Plans) | C6: Get-SpendByPricingModel.ps1 | D6: DataCollection\SpendByPricingModel.csv
B7: 2. Last month's Azure PAYG spend on virtual machines, grouped by meter subcategory (which corresponds to VM family) | C7: Get-SpendByVMFamily.ps1 | D7: DataCollection\SpendByVMFamily.csv
A9: Instructions for use
A10: 1. Execute the two PowerShell scripts above.
A11: 2. Check that two CSV files with data have been created in folder DataCollection
A12: 3. In tab Parameters, enter the appropriate currency and any applicable discounts. Provide the full path to the directory containing the two CSV files.
A13: 4. Click menu Data and select Queries and Connections. This window should appear as a pane on the right of the screen.
A14: 5. Navigate to tab Data - SpendByPricingModel and click the refresh button next to the query with this name, in the right-hand pane. If the query runs successfully and finds the CSV file, the contents will be loaded into this tab.
A15: 6. Navigate to tab Data - SpendByVMFamily and click the refresh button next to the query with this name, in the right-hand pane. If the query runs successfully and finds the CSV file, the contents will be loaded into this tab.
A16: 7. Once both tabs are populated, move on to the DiscountCalculator tab and refresh the query with the same name. This query calculates the potential savings for each VM family by using reservations of savings plan.
A17: Important: If any of the last four columns are blank, it is usually due to missing discount data in the Discounts tab. Use the Azure Price Calculator to find the discounts for that family and enter them in a new row at the bottom of the table. Refresh the query and repeat until all rows have discount information.
A18: 8. Navigate to tab Pivots and refresh both pivot tables via menu PivotTable Analyze => Refresh All
A19: 9. Navigate to tab Savings Plan and start modeling!

Sheet Parameters
A1: Parameters specific to the customer
A2: Note: These discounts should be the ones that were active during the last 6 months, in order to give a true picture of the historical spend
A4: Customer name | B4: Contoso
A5: Pricing currency | B5: USD | C5: For customers with a Microsoft Customer Agreement, pricing currency is always USD
A6: Customer PAYG discount | B6: 0.1 | C6: % through EA or MCA agreement, also known as ACD or Azure Consumption Discount
A7: Customer RI discount, if any | B7: 0 | C7: % Extra discounts on reservations, if any
A8: Customer SP discount, if any | B8: 0 | C8: % Extra discount on savings plans, if any
A9: Estimated monthly growth | B9: 0.02 | C9: Estimated growth of the workload per month
A10: Data collection script directory | B10: C:\Users\dohughes\OneDrive - Microsoft\Documents\GitHub\azure\projects\SavingsPlanCalculator\DataCollection\Sample

Sheet Data - SpendByPricingModel
A1: BillingMonth | B1: PricingModel | C1: Currency | D1: PreTaxCost
A2: 45992 | B2: OnDemand | C2: USD | D2: 21455.807
A3: 45992 | B3: Reservation | C3: USD | D3: 160.47963
A4: 45992 | B4: SavingsPlan | C4: USD | D4: 250
A5: 46023 | B5: OnDemand | C5: USD | D5: 21551.587
A6: 46023 | B6: Reservation | C6: USD | D6: 160.48379
A7: 46023 | B7: SavingsPlan | C7: USD | D7: 225
A8: 46054 | B8: OnDemand | C8: USD | D8: 19243.61
A9: 46054 | B9: Reservation | C9: USD | D9: 144.93369
A10: 46054 | B10: SavingsPlan | C10: USD | D10: 150
A11: 46082 | B11: OnDemand | C11: USD | D11: 21028.305
A12: 46082 | B12: Reservation | C12: USD | D12: 146.15097
A13: 46082 | B13: SavingsPlan | C13: USD | D13: 208
... A19: 46143 | B19: SavingsPlan | C19: USD | D19: 220

Sheet Data - SpendByVMFamily
A1: BillingMonth | B1: MeterCategory | C1: MeterSubCategory | D1: Currency | E1: PreTaxCost
A2: 46143 | B2: Virtual Machines | C2: BS Series | D2: USD | E2: 268.81377
A3: 46143 | B3: Virtual Machines | C3: Dav4/Dasv4 Series | D3: USD | E3: 590.94907
A4: 46143 | B4: Virtual Machines | C4: Ddsv4 Series | D4: USD | E4: 217.29151
A5: 46143 | B5: Virtual Machines | C5: Ddv4 Series | D5: USD | E5: 505.37846
A6: 46143 | B6: Virtual Machines | C6: Dsv4 Series | D6: USD | E6: 143.84967
A7: 46143 | B7: Virtual Machines | C7: Dv2/DSv2 Series | D7: USD | E7: 3986.7899
A8: 46143 | B8: Virtual Machines | C8: Dv2/DSv2 Series Windows | D8: USD | E8: 108.58753
A9: 46143 | B9: Virtual Machines | C9: Dv3/DSv3 Series | D9: USD | E9: 1578.665
A10: 46143 | B10: Virtual Machines | C10: Easv5 Series | D10: USD | E10: 15.563871
A11: 46143 | B11: Virtual Machines | C11: Eav4/Easv4 Series | D11: USD | E11: 42.906309
A12: 46143 | B12: Virtual Machines | C12: Laosv4 Series | D12: USD | E12: 54.955681
A13: 46143 | B13: Virtual Machines | C13: NCSv3 Series Windows | D13: USD | E13: 13838.09

Sheet DiscountCalculator
A1: BillingMonth | B1: MeterCategory | C1: MeterSubCategory | D1: Currency | E1: PreTaxCost | F1: RI1YDisc | G1: RI3YDisc | H1: SP1YDisc | I1: SP3YDisc | J1: ListPrice | K1: RI1YPrice | L1: RI3YPrice | M1: SP1YPrice | N1: SP3YPrice
A2: 46143 | B2: Virtual Machines | C2: BS Series | D2: USD | E2: 268.81377 | F2: 0.41 | H2: 0.24 | I2: 0.45 | J2: 298.68197 | K2: 176.22236 | L2: 268.81377 | M2: 226.9983 | N2: 164.27508
A3: 46143 | B3: Virtual Machines | C3: Dav4/Dasv4 Series | D3: USD | E3: 590.94907 | F3: 0.33 | G3: 0.54 | H3: 0.24 | I3: 0.45 | J3: 656.61008 | K3: 439.92875 | L3: 302.04064 | M3: 499.02366 | N3: 361.13554
A4: 46143 | B4: Virtual Machines | C4: Ddsv4 Series | D4: USD | E4: 217.29151 | F4: 0.41 | G4: 0.62 | H4: 0.24 | I4: 0.45 | J4: 241.43501 | K4: 142.44666 | L4: 91.745304 | M4: 183.49061 | N4: 132.78926
A5: 46143 | B5: Virtual Machines | C5: Ddv4 Series | D5: USD | E5: 505.37846 | F5: 0.41 | G5: 0.62 | H5: 0.24 | I5: 0.45 | J5: 561.53162 | K5: 331.30366 | L5: 213.38202 | M5: 426.76403 | N5: 308.84239
A6: 46143 | B6: Virtual Machines | C6: Dsv4 Series | D6: USD | E6: 143.84967 | F6: 0.41 | G6: 0.62 | H6: 0.24 | I6: 0.45 | J6: 159.83297 | K6: 94.30145 | L6: 60.736527 | M6: 121.47305 | N6: 87.908131
A7: 46143 | B7: Virtual Machines | C7: Dv2/DSv2 Series | D7: USD | E7: 3986.7899 | F7: 0.4 | H7: 0.24 | I7: 0.45 | J7: 4429.7665 | K7: 2657.8599 | L7: 3986.7899 | M7: 3366.6226 | N7: 2436.3716
A8: 46143 | B8: Virtual Machines | C8: Dv2/DSv2 Series Windows | D8: USD | E8: 108.58753 | F8: 0.4 | H8: 0.24 | I8: 0.45 | J8: 120.65281 | K8: 72.391686 | L8: 108.58753 | M8: 91.696135 | N8: 66.359045
A9: 46143 | B9: Virtual Machines | C9: Dv3/DSv3 Series | D9: USD | E9: 1578.665 | F9: 0.36 | G9: 0.56 | H9: 0.24 | I9: 0.45 | J9: 1754.0722 | K9: 1122.6062 | L9: 771.79176 | M9: 1333.0949 | N9: 964.7397
A10: 46143 | B10: Virtual Machines | C10: Easv5 Series | D10: USD | E10: 15.563871 | F10: 0.41 | G10: 0.62 | H10: 0.32 | I10: 0.53 | J10: 17.29319 | K10: 10.202982 | L10: 6.571412 | M10: 11.759369 | N10: 8.1277991
A11: 46143 | B11: Virtual Machines | C11: Eav4/Easv4 Series | D11: USD | E11: 42.906309 | F11: 0.41 | G11: 0.61 | H11: 0.32 | I11: 0.53 | J11: 47.673676 | K11: 28.127469 | L11: 18.592734 | M11: 32.4181 | N11: 22.406628
A12: 46143 | B12: Virtual Machines | C12: Laosv4 Series | D12: USD | E12: 54.955681 | F12: 0.36 | G12: 0.62 | H12: 0.27 | I12: 0.54 | J12: 61.061868 | K12: 39.079595 | L12: 23.20351 | M12: 44.575163 | N12: 28.088459
A13: 46143 | B13: Virtual Machines | C13: NCSv3 Series Windows | D13: USD | E13: 13838.09 | H13: 0.27 | I13: 0.47 | J13: 15375.656 | K13: 13838.09 | L13: 13838.09 | M13: 11224.229 | N13: 8149.0977
A14: Total | E14: =SUBTOTAL(109,DiscountCalculator[PreTaxCost]) -> 21351.841 | J14: =SUBTOTAL(109,DiscountCalculator[ListPrice]) -> 23724.268 | K14: =SUBTOTAL(109,DiscountCalculator[RI1YPrice]) -> 18952.561 | L14: =SUBTOTAL(109,DiscountCalculator[RI3YPrice]) -> 19690.345 | M14: =SUBTOTAL(109,DiscountCalculator[SP1YPrice]) -> 17562.145 | N14: =SUBTOTAL(109,DiscountCalculator[SP3YPrice]) -> 12730.141

Sheet Pivots
A1: Pivot 1: PAYG Spend | D1: Pivot 2: Commitment Spend
A3: PricingModel | B3: OnDemand | D3: PricingModel | E3: (Multiple Items)
A5: Row Labels | B5: Sum of PreTaxCost | D5: Row Labels | E5: Sum of PreTaxCost
A6: 45992 | B6: 21455.807 | D6: 45992 | E6: 410.47963
A7: 46023 | B7: 21551.587 | D7: 46023 | E7: 385.48379
A8: 46054 | B8: 19243.61 | D8: 46054 | E8: 294.93369
A9: 46082 | B9: 21028.305 | D9: 46082 | E9: 354.15097
A10: 46113 | B10: 20297.512 | D10: 46113 | E10: 324.96209
A11: 46143 | B11: 21351.841 | D11: 46143 | E11: 359.45049
A12: Grand Total | B12: 124928.66 | D12: Grand Total | E12: 2129.4607

Sheet Summary
A1: Summary
A2: What we paid in PAYG VM costs | B2: =DiscountCalculator[[#Totals],[PreTaxCost]] -> 21351.841 | C2: =CURR -> USD
A3: What we would pay with RI1Y | B3: =DiscountCalculator[[#Totals],[RI1YPrice]] -> 18952.561 | C3: =CURR -> USD | D3: leading to an overall discount of | E3: =1-(B3/$B$2) -> 0.11236876 | F3: For information only, not used in this calculator
A4: What we would pay with RI3Y | B4: =DiscountCalculator[[#Totals],[RI3YPrice]] -> 19690.345 | C4: =CURR -> USD | D4: leading to an overall discount of | E4: =1-(B4/$B$2) -> 0.077815099 | F4: For information only, not used in this calculator
A5: What we would pay with SP1Y | B5: =DiscountCalculator[[#Totals],[SP1YPrice]] -> 17562.145 | C5: =CURR -> USD | D5: leading to an overall discount of | E5: =1-(B5/$B$2) -> 0.17748804 | F5: Used in the Savings Plan tab when choosing 12 month term
A6: What we would pay with SP3Y | B6: =DiscountCalculator[[#Totals],[SP3YPrice]] -> 12730.141 | C6: =CURR -> USD | D6: leading to an overall discount of | E6: =1-(B6/$B$2) -> 0.40379187 | F6: Used in the Savings Plan tab when choosing 36 month term

Sheet SavingsPlan
B1: ="Modelling the purchase of Azure Savings Plan for Compute for "&CUSTNAME -> Modelling the purchase of Azure Savings Plan for Compute for Contoso
B3: 1. Make sure that all tabs are showing data and that the queries have run successfully.
B4: 2. Select the term of your savings plan, which will fetch the calculated overall discounts.
B5: 3. Adjust the slider to model the purchase of different quantities of savings plan.
B6: 4. If needed, adjust the Slider maximum value to be higher or lower. When the slider is in the middle you should have an even split of blue and green on the graph.
B8: Currency | C8: =CURR -> USD
B9: PAYG discount (ACD) | C9: =PAYGDISC -> 0.1
B10: SP discount | C10: =IF(C12=12,AVGDISCSP1Y,AVGDISCSP3Y) -> 0.17748804 | D10: Calculated | H10: 31
B11: SP commitment | C11: =H10*H14/100 -> 12.4 | D11: =CURR&"/hr" -> USD/hr | H11: Drag the slider to adjust commitment
B12: Savings plan term | C12: 12 | D12: months
B13: SP break-even point | C13: =C12*(1-SPDISC) -> 9.8701435 | D13: months
G14: Slider max | H14: 40 | I14: =CURR&"/hr" -> USD/hr
C16: Before | H16: After
B17: Month | C17: AllUp Cost | D17: PAYG Cost | E17: RI/SP Cost | F17: Split | G17: New SP Cost | H17: AllUp Cost | I17: PAYG Cost | J17: RI/SP Cost | K17: New Split | L17: Savings
A18: History | B18: =Pivots!A6 -> 45992 | C18: =D18+E18 -> 21866.286 | D18: =GETPIVOTDATA("PreTaxCost",Pivots!$A$5,"BillingMonth",B18) -> 21455.807 | E18: =GETPIVOTDATA("PreTaxCost",Pivots!$D$5,"BillingMonth",B18) -> 410.47963 | F18: =MAX(0,ROUND(D18/C18*100,0))&" / "&MIN(100,100-ROUND(D18/C18*100,0)) -> 98 / 2 | G18: =SPCOMMIT*730 -> 9052 | H18: =E18+G18+I18 -> 19912.975 | I18: =MAX(0,D18-G18/(1-SPDISC)) -> 10450.496 | J18: =E18+G18 -> 9462.4796 | K18: =ROUND(I18/H18*100,0)&" / "&100-ROUND(I18/H18*100,0) -> 52 / 48 | L18: =C18-H18 -> 1953.3111
B19: =Pivots!A7 -> 46023 | C19: =D19+E19 -> 21937.071 | D19: =GETPIVOTDATA("PreTaxCost",Pivots!$A$5,"BillingMonth",B19) -> 21551.587 | E19: =GETPIVOTDATA("PreTaxCost",Pivots!$D$5,"BillingMonth",B19) -> 385.48379 | F19: =MAX(0,ROUND(D19/C19*100,0))&" / "&MIN(100,100-ROUND(D19/C19*100,0)) -> 98 / 2 | G19: =SPCOMMIT*730 -> 9052 | H19: =E19+G19+I19 -> 19983.76 | I19: =MAX(0,D19-G19/(1-SPDISC)) -> 10546.276 | J19: =E19+G19 -> 9437.4838 | K19: =ROUND(I19/H19*100,0)&" / "&100-ROUND(I19/H19*100,0) -> 53 / 47 | L19: =C19-H19 -> 1953.3111
B20: =Pivots!A8 -> 46054 | C20: =D20+E20 -> 19538.544 | D20: =GETPIVOTDATA("PreTaxCost",Pivots!$A$5,"BillingMonth",B20) -> 19243.61 | E20: =GETPIVOTDATA("PreTaxCost",Pivots!$D$5,"BillingMonth",B20) -> 294.93369 | F20: =MAX(0,ROUND(D20/C20*100,0))&" / "&MIN(100,100-ROUND(D20/C20*100,0)) -> 98 / 2 | G20: =SPCOMMIT*730 -> 9052 | H20: =E20+G20+I20 -> 17585.233 | I20: =MAX(0,D20-G20/(1-SPDISC)) -> 8238.299 | J20: =E20+G20 -> 9346.9337 | K20: =ROUND(I20/H20*100,0)&" / "&100-ROUND(I20/H20*100,0) -> 47 / 53 | L20: =C20-H20 -> 1953.3111
B21: =Pivots!A9 -> 46082 | C21: =D21+E21 -> 21382.456 | D21: =GETPIVOTDATA("PreTaxCost",Pivots!$A$5,"BillingMonth",B21) -> 21028.305 | E21: =GETPIVOTDATA("PreTaxCost",Pivots!$D$5,"BillingMonth",B21) -> 354.15097 | F21: =MAX(0,ROUND(D21/C21*100,0))&" / "&MIN(100,100-ROUND(D21/C21*100,0)) -> 98 / 2 | G21: =SPCOMMIT*730 -> 9052 | H21: =E21+G21+I21 -> 19429.145 | I21: =MAX(0,D21-G21/(1-SPDISC)) -> 10022.994 | J21: =E21+G21 -> 9406.151 | K21: =ROUND(I21/H21*100,0)&" / "&100-ROUND(I21/H21*100,0) -> 52 / 48 | L21: =C21-H21 -> 1953.3111
B22: =Pivots!A10 -> 46113 | C22: =D22+E22 -> 20622.474 | D22: =GETPIVOTDATA("PreTaxCost",Pivots!$A$5,"BillingMonth",B22) -> 20297.512 | E22: =GETPIVOTDATA("PreTaxCost",Pivots!$D$5,"BillingMonth",B22) -> 324.96209 | F22: =MAX(0,ROUND(D22/C22*100,0))&" / "&MIN(100,100-ROUND(D22/C22*100,0)) -> 98 / 2 | G22: =SPCOMMIT*730 -> 9052 | H22: =E22+G22+I22 -> 18669.163 | I22: =MAX(0,D22-G22/(1-SPDISC)) -> 9292.2013 | J22: =E22+G22 -> 9376.9621 | K22: =ROUND(I22/H22*100,0)&" / "&100-ROUND(I22/H22*100,0) -> 50 / 50 | L22: =C22-H22 -> 1953.3111
B23: =Pivots!A11 -> 46143 | C23: =D23+E23 -> 21711.292 | D23: =GETPIVOTDATA("PreTaxCost",Pivots!$A$5,"BillingMonth",B23) -> 21351.841 | E23: =GETPIVOTDATA("PreTaxCost",Pivots!$D$5,"BillingMonth",B23) -> 359.45049 | F23: =MAX(0,ROUND(D23/C23*100,0))&" / "&MIN(100,100-ROUND(D23/C23*100,0)) -> 98 / 2 | G23: =SPCOMMIT*730 -> 9052 | H23: =E23+G23+I23 -> 19757.98 | I23: =MAX(0,D23-G23/(1-SPDISC)) -> 10346.53 | J23: =E23+G23 -> 9411.4505 | K23: =ROUND(I23/H23*100,0)&" / "&100-ROUND(I23/H23*100,0) -> 52 / 48 | L23: =C23-H23 -> 1953.3111
A24: Forecast | B24: =EDATE(B23,1) -> 46174 | C24: =C23*(1+GROWTH) -> 22145.517 | D24: =D23*(1+GROWTH) -> 21778.878 | E24: =C24-D24 -> 366.6395 | F24: =MAX(0,ROUND(D24/C24*100,0))&" / "&MIN(100,100-ROUND(D24/C24*100,0)) -> 98 / 2 | G24: =SPCOMMIT*730 -> 9052 | H24: =E24+G24+I24 -> 20192.206 | I24: =MAX(0,D24-G24/(1-SPDISC)) -> 10773.567 | J24: =E24+G24 -> 9418.6395 | K24: =ROUND(I24/H24*100,0)&" / "&100-ROUND(I24/H24*100,0) -> 53 / 47 | L24: =C24-H24 -> 1953.3111
B25: =EDATE(B24,1) -> 46204 | C25: =C24*(1+GROWTH) -> 22588.428 | D25: =D24*(1+GROWTH) -> 22214.455 | E25: =C25-D25 -> 373.97229 | F25: =MAX(0,ROUND(D25/C25*100,0))&" / "&MIN(100,100-ROUND(D25/C25*100,0)) -> 98 / 2 | G25: =SPCOMMIT*730 -> 9052 | H25: =E25+G25+I25 -> 20635.117 | I25: =MAX(0,D25-G25/(1-SPDISC)) -> 11209.144 | J25: =E25+G25 -> 9425.9723 | K25: =ROUND(I25/H25*100,0)&" / "&100-ROUND(I25/H25*100,0) -> 54 / 46 | L25: =C25-H25 -> 1953.3111
B26: =EDATE(B25,1) -> 46235 | C26: =C25*(1+GROWTH) -> 23040.196 | D26: =D25*(1+GROWTH) -> 22658.745 | E26: =C26-D26 -> 381.45174 | F26: =MAX(0,ROUND(D26/C26*100,0))&" / "&MIN(100,100-ROUND(D26/C26*100,0)) -> 98 / 2 | G26: =SPCOMMIT*730 -> 9052 | H26: =E26+G26+I26 -> 21086.885 | I26: =MAX(0,D26-G26/(1-SPDISC)) -> 11653.433 | J26: =E26+G26 -> 9433.4517 | K26: =ROUND(I26/H26*100,0)&" / "&100-ROUND(I26/H26*100,0) -> 55 / 45 | L26: =C26-H26 -> 1953.3111
B27: =EDATE(B26,1) -> 46266 | C27: =C26*(1+GROWTH) -> 23501 | D27: =D26*(1+GROWTH) -> 23111.919 | E27: =C27-D27 -> 389.08077 | F27: =MAX(0,ROUND(D27/C27*100,0))&" / "&MIN(100,100-ROUND(D27/C27*100,0)) -> 98 / 2 | G27: =SPCOMMIT*730 -> 9052 | H27: =E27+G27+I27 -> 21547.689 | I27: =MAX(0,D27-G27/(1-SPDISC)) -> 12106.608 | J27: =E27+G27 -> 9441.0808 | K27: =ROUND(I27/H27*100,0)&" / "&100-ROUND(I27/H27*100,0) -> 56 / 44 | L27: =C27-H27 -> 1953.3111
B28: =EDATE(B27,1) -> 46296 | C28: =C27*(1+GROWTH) -> 23971.02 | D28: =D27*(1+GROWTH) -> 23574.158 | E28: =C28-D28 -> 396.86239 | F28: =MAX(0,ROUND(D28/C28*100,0))&" / "&MIN(100,100-ROUND(D28/C28*100,0)) -> 98 / 2 | G28: =SPCOMMIT*730 -> 9052 | H28: =E28+G28+I28 -> 22017.709 | I28: =MAX(0,D28-G28/(1-SPDISC)) -> 12568.847 | J28: =E28+G28 -> 9448.8624 | K28: =ROUND(I28/H28*100,0)&" / "&100-ROUND(I28/H28*100,0) -> 57 / 43 | L28: =C28-H28 -> 1953.3111
B29: =EDATE(B28,1) -> 46327 | C29: =C28*(1+GROWTH) -> 24450.441 | D29: =D28*(1+GROWTH) -> 24045.641 | E29: =C29-D29 -> 404.79964 | F29: =MAX(0,ROUND(D29/C29*100,0))&" / "&MIN(100,100-ROUND(D29/C29*100,0)) -> 98 / 2 | G29: =SPCOMMIT*730 -> 9052 | H29: =E29+G29+I29 -> 22497.13 | I29: =MAX(0,D29-G29/(1-SPDISC)) -> 13040.33 | J29: =E29+G29 -> 9456.7996 | K29: =ROUND(I29/H29*100,0)&" / "&100-ROUND(I29/H29*100,0) -> 58 / 42 | L29: =C29-H29 -> 1953.3111
B30: History only (6 months) | C30: =SUM(C18:C23) -> 127058.12 | D30: =SUM(D18:D23) -> 124928.66 | E30: =SUM(E18:E23) -> 2129.4607 | F30: =MAX(0,ROUND(D30/C30*100,0))&" / "&MIN(100,100-ROUND(D30/C30*100,0)) -> 98 / 2 | G30: =SUM(G18:G23) -> 54312 | H30: =SUM(H18:H23) -> 115338.26 | I30: =MAX(0,D30-G30/(1-SPDISC)) -> 58896.796 | J30: =E30+G30 -> 56441.461 | K30: =ROUND(I30/H30*100,0)&" / "&100-ROUND(I30/H30*100,0) -> 51 / 49 | L30: =SUM(L18:L23) -> 11719.866
B31: Forecast only (6 months) | C31: =SUM(C24:C29) -> 139696.6 | D31: =SUM(D24:D29) -> 137383.8 | E31: =SUM(E24:E29) -> 2312.8063 | F31: =MAX(0,ROUND(D31/C31*100,0))&" / "&MIN(100,100-ROUND(D31/C31*100,0)) -> 98 / 2 | G31: =SUM(G24:G29) -> 54312 | H31: =SUM(H24:H29) -> 127976.74 | I31: =MAX(0,D31-G31/(1-SPDISC)) -> 71351.93 | J31: =E31+G31 -> 56624.806 | K31: =ROUND(I31/H31*100,0)&" / "&100-ROUND(I31/H31*100,0) -> 56 / 44 | L31: =SUM(L24:L29) -> 11719.866

Sheet Discounts
A1: What are the offered discounts on VM SKUs?
A2: This data can be collected from the Azure public portal. Eventual customer-specific discounts on reservations or savings plans are added later.
A3: Discounts can vary slightly between regions. These are taken using West Europe as a typical region.
B5: List discounts
A6: MeterSubCategory | B6: RI1Y | C6: RI3Y | D6: SP1Y | E6: SP3Y
A7: Av2 Series | B7: 0.41 | D7: 0.25 | E7: 0.46
A8: Av2 Series Windows | B8: 0.41 | D8: 0.25 | E8: 0.46
A9: Basv2 Series | B9: 0.41 | C9: 0.62 | D9: 0.24 | E9: 0.45
A10: Basv2 Series Windows | B10: 0.41 | C10: 0.62 | D10: 0.24 | E10: 0.45
A11: Bpsv2 Series | B11: 0.41 | C11: 0.62 | D11: 0.24 | E11: 0.45
A12: BS Series | B12: 0.41 | D12: 0.24 | E12: 0.45
A13: BS Series Windows | B13: 0.41 | D13: 0.24 | E13: 0.45
A14: Bsv2 Series | B14: 0.41 | C14: 0.62 | D14: 0.24 | E14: 0.45
A15: Bsv2 Series VM | B15: 0.41 | C15: 0.62 | D15: 0.24 | E15: 0.45
A16: Bsv2 Series Windows | B16: 0.41 | C16: 0.62 | D16: 0.24 | E16: 0.45
A17: D/DS Series | B17: 0.27 | D17: 0.24 | E17: 0.45
A18: Dadsv5 Series | B18: 0.41 | C18: 0.62 | D18: 0.24 | E18: 0.45
A19: Dadsv5 Series VM | B19: 0.41 | C19: 0.62 | D19: 0.24 | E19: 0.45
A20: Dadsv5 Series Windows | B20: 0.41 | C20: 0.62 | D20: 0.24 | E20: 0.45
A21: Dadsv6 Series | B21: 0.41 | C21: 0.62 | D21: 0.29 | E21: 0.53
A22: Dadsv7 Series | B22: 0.41 | C22: 0.62 | D22: 0.29 | E22: 0.53
A23: Daldsv6 Series | B23: 0.41 | C23: 0.62 | D23: 0.29 | E23: 0.53
A24: Daldsv7 Series | B24: 0.41 | C24: 0.62 | D24: 0.29 | E24: 0.53
A25: Dalsv6 Series | B25: 0.41 | C25: 0.62 | D25: 0.29 | E25: 0.53
A26: Dalsv7 Series | B26: 0.41 | C26: 0.62 | D26: 0.29 | E26: 0.53
A27: Dasv4 Series VM | B27: 0.33 | C27: 0.54 | D27: 0.24 | E27: 0.45
A28: Dasv5 Series | B28: 0.41 | C28: 0.62 | D28: 0.24 | E28: 0.45
A29: Dasv5 Series Windows | B29: 0.41 | C29: 0.62 | D29: 0.24 | E29: 0.45
... A43: DCesv6 Series | B43: 0.38 | C43: 0.61 | D43: 0.31 | E43: 0.54
A44: DCSv2 Series | D44: 0.17 | E44: 0.38
A45: DCsv3 Series Linux | B45: 0.2 | C45: 0.4 | D45: 0.11 | E45: 0.29
A46: Ddsv4 Series | B46: 0.41 | C46: 0.62 | D46: 0.24 | E46: 0.45
A47: Ddsv5 Series | B47: 0.41 | C47: 0.62 | D47: 0.24 | E47: 0.45
A48: Ddsv5 Series Windows | B48: 0.41 | C48: 0.62 | D48: 0.24 | E48: 0.45
A49: Ddsv6 Series | B49: 0.38 | C49: 0.61 | D49: 0.31 | E49: 0.54
A50: Ddsv7-series Linux | D50: 0.24 | E50: 0.46
A51: Ddv4 Series | B51: 0.41 | C51: 0.62 | D51: 0.24 | E51: 0.45
A52: Ddv4 Series Windows | B52: 0.41 | C52: 0.62 | D52: 0.24 | E52: 0.45
A53: Ddv5 Series | B53: 0.41 | C53: 0.62 | D53: 0.24 | E53: 0.45
A54: Dldsv5 Series | B54: 0.41 | C54: 0.64 | D54: 0.26 | E54: 0.48
...
